Workbook

Sheet 0_README
A1: LAB THỰC CHIẾN DAY 22: AI MONETIZATION, UNIT ECONOMICS & GTM STRATEGY
A2: Học viên: Nguyễn Thị Minh Khánh | Mã học viên: 2A202602546 | Repository: Track1_Day22_2A202602546_NguyenThiMinhKhanh
A3: Ngày chốt giá API & Benchmark: 26/08/2026 | Tỷ giá quy đổi: 26,000 VND / USD
A5: QUY ƯỚC MÀU TRONG BẢNG TÍNH
A6: Màu sắc | B6: Tên quy ước | C6: Ý nghĩa / Hành động của người làm bài | D6: Ví dụ áp dụng
A7: 🟡 MÀU VÀNG | B7: User Input | C7: Ô người làm bài BẮT BUỘC phải điền số liệu / thông tin giả định | D7: Giá API, số turn, containment rate
A8: ⬜ MÀU XÁM | B8: Formula / Calculated | C8: Công thức tự động tính toán - TUYỆT ĐỐI KHÔNG ĐƯỢC GHI ĐÈ | D8: Tổng LLM cost, Cost/Job, CAC Budget
A9: 🟩 MÀU XANH LÁ | B9: Target Achieved / Healthy | C9: Chỉ số đạt ngưỡng chuẩn an toàn tài chính (Gross Margin >= 60%, LTV:CAC >= 3) | D9: Gross Margin 72%, Payback 4.5 tháng
A10: 🟥 MÀU ĐỎ / CAM | B10: Alert / Unhealthy | C10: Chỉ số rơi vào vùng nguy hiểm tài chính - Cần điều chỉnh mô hình | D10: Gross Margin < 50%, Deal/AE > 1 deal/ngày
A13: BẢN ĐỒ CÁC TAB LÀM VIỆC VÀ NỘI DUNG CHÍNH
A14: Tab | B14: Tên Tab | C14: Vai trò & Nội dung chi tiết | D14: Đầu ra cốt lõi (Key Deliverables)
A15: Tab 0 | B15: 0_README | C15: Hướng dẫn quy ước, ngày chốt giá, danh mục các tab | D15: Bản đồ cấu trúc làm bài
A16: Tab 1 | B16: 1_Cost_Job | C16: Tab nặng nhất: Tính Cost/Job đầy đủ 5 thành phần (LLM + Infra + HITL + Retry + Overhead) | D16: Cost/Job hoàn thành (Biến thể A & B)
A17: Tab 2 | B17: 2_Pricing | C17: Tính giá sàn (3x Cost/Job), neo giá trần, xác định Gross Margin và Stress Test Breakeven | D17: Giá đề xuất ($0.60), Gross Margin (72%), Breakeven (68.4%)
A18: Tab 3 | B18: 3_Value_Metric | C18: Đánh giá ma trận Attribution x Autonomy, benchmark thị trường, chốt đơn vị tính tiền | D18: Value Metric bảo vệ được (Hybrid/Outcome)
A19: Tab 4 | B19: 4_Channel_Fit | C19: Tính Ngân sách CAC, Deal/AE capacity, Channel Affordability Test, chọn 1 kênh GTM | D19: Kênh Partner-Led (Pancake/Haravan) + CAC Budget ($2,592)
A20: Tab 5 | B20: 5_90Day_Plan | C20: Xác định Pain Moment 3 phần, Điểm nhúng zero-friction, Kế hoạch 90 ngày & Evidence Pack | D20: Pain Moment, 90-Day Plan, 3 Tài sản Evidence Pack
A21: Tab 6 | B21: 6_Benchmarks | C21: Bảng giá tham chiếu API chính thức và Benchmark tài chính B2B SaaS/AI từ Bessemer, ICONIQ | D21: Nguồn dữ liệu đối soát chuẩn mực

Sheet 1_Cost_Job
A1: TAB 1: TÍNH TOÁN COST/JOB ĐẦY ĐỦ 5 THÀNH PHẦN (UNIT ECONOMICS MODEL)
A2: Sản phẩm: AutoSupport AI | Job: Tự động giải quyết dứt điểm ticket CSKH đa kênh (E-commerce / D2C SME)
A4: SECTION 1: ĐỊNH NGHĨA JOB & ĐÓNG GÓI SẢN PHẨM
A5: Tên sản phẩm AI | B5: AutoSupport AI - Autonomous Customer Support Resolution Agent
A6: Câu mô tả sản phẩm (Bản A - Tool) | B6: Công cụ AI Copilot hỗ trợ nhân viên CSKH tra cứu và soạn câu trả lời nhanh.
A7: Câu mô tả sản phẩm (Bản B - Job) | B7: Agent AI tự động tiếp nhận, tra cứu chính sách/vận đơn và giải quyết dứt điểm ticket CSKH ca đêm mà không cần nhân sự trực ca.
A8: Phiên bản lựa chọn & Ngân sách | B8: Chọn Phiên bản B: Đánh trực tiếp vào Ngân sách Vận hành / Nhân sự trực ca (Ops Headcount Budget) - Ngân sách lớn và quyết nhanh.
A9: Định nghĩa 1 Job HOÀN THÀNH | B9: 1 ticket CSKH được giải quyết dứt điểm: Khách hàng xác nhận vấn đề đã xong hoặc không phản hồi lại sau 24h, và không bị escalate sang người.
A10: Phân loại trách nhiệm HITL | B10: Biến thể B (Managed Outcome - AI gánh vác xử lý cam kết trọn gói, có tính chi phí nhân sự escalation vào COGS)
A12: SECTION 2: KHỐI LƯỢNG VẬN HÀNH & CONTAINMENT RATE (THÁNG)
A13: Khoản mục | B13: Giá trị | C13: Đơn vị | D13: Công thức / Nguồn cơ sở | E13: Ghi chú
A14: Tổng số ticket tiếp nhận (Jobs Attempted) | B14: 2000 | C14: tickets/tháng | D14: Giả định quy mô 1 shop E-commerce SMB | E14: Input biến số quy mô
A15: Tỷ lệ AI tự xử lý thành công (Containment Rate) | B15: 0.82 | C15: % | D15: Benchmark Intercom Fin 82% / Kết quả Eval | E15: Biến sinh tử của bài toán
A16: Số Job AI HOÀN THÀNH (Jobs Completed - Mẫu số thật) | B16: =B14*B15 | C16: jobs/tháng | D16: =B14 * B15 | E16: MẪU SỐ BẮT BUỘC ĐỂ CHIA COST/JOB
A17: Số ticket chuyển sang người (Escalations) | B17: =B14*(1-B15) | C17: tickets/tháng | D17: =B14 * (1 - B15) | E17: Cần người giải quyết
A19: SECTION 3: CHI PHÍ LLM API (CÓ PROMPT CACHING & FRESH TOKENS)
A20: Khoản mục | B20: Giá trị | C20: Đơn vị | D20: Công thức / Nguồn cơ sở | E20: Ghi chú
A21: Mô hình LLM chính sử dụng | B21: Anthropic Claude 3.5 Haiku (hoặc Gemini 3.7 Flash) | C21: text | D21: Anthropic Pricing 26/08/2026 | E21: Model tối ưu speed/cost
A22: Giá Fresh Input per 1M tokens | B22: 1 | C22: $/1M | D22: Anthropic List Pricing | E22: Giá niêm yết
A23: Giá Output per 1M tokens | B23: 5 | C23: $/1M | D23: Anthropic List Pricing | E23: Giá niêm yết
A24: Giá Prompt Cache Write per 1M tokens | B24: 1.25 | C24: $/1M | D24: 1.25x Input Price (Anthropic) | E24: Ghi vào cache lượt đầu
A25: Giá Prompt Cache Read per 1M tokens | B25: 0.1 | C25: $/1M | D25: 0.10x Input Price (Anthropic) | E25: Đọc từ cache các lượt sau
A26: Số lượt hội thoại (turns) trung bình / ticket | B26: 6 | C26: turns | D26: Thống kê thực tế CSKH | E26: 6 lượt qua lại bot - khách
A27: System Prompt + Knowledge Base (Cache được) | B27: 3000 | C27: tokens | D27: System prompt + FAQ/Catalog | E27: Được cache từ turn 2
A28: Fresh Input token / lượt hội thoại | B28: 500 | C28: tokens/turn | D28: User message + context mới | E28: 500 tokens x 6 turns
A29: Output token / lượt hội thoại | B29: 150 | C29: tokens/turn | D29: Bot response | E29: 150 tokens x 6 turns
A30: Chi phí Cache Write (1 lần / ticket) | B30: =B27*B24/1000000 | C30: $/ticket | D30: =B27 * B24 / 1M | E30: Lượt đầu tiên ghi cache
A31: Chi phí Cache Read ((turns - 1) lần / ticket) | B31: =(B26-1)*B27*B25/1000000 | C31: $/ticket | D31: =(B26 - 1) * B27 * B25 / 1M | E31: 5 lượt sau đọc từ cache
A32: Chi phí Fresh Input (turns lần / ticket) | B32: =B26*B28*B22/1000000 | C32: $/ticket | D32: =B26 * B28 * B22 / 1M | E32: Input tin nhắn mới
A33: Chi phí Output (turns lần / ticket) | B33: =B26*B29*B23/1000000 | C33: $/ticket | D33: =B26 * B29 * B23 / 1M | E33: Output trả về của bot
A34: Tổng chi phí LLM / ticket (CÓ CACHE) | B34: =SUM(B30:B33) | C34: $/ticket | D34: =B30 + B31 + B32 + B33 | E34: Chi phí tối ưu thực tế
A35: Tổng chi phí LLM / ticket (NẾU KHÔNG CACHE) | B35: =(B26*(B27+B28)*B22 + B26*B29*B23)/1000000 | C35: $/ticket | D35: =(Turns*(Cache+Fresh)*Input + Turns*Out*Output)/1M | E35: Chi phí nếu không cache
A36: % Tiết kiệm nhờ Prompt Caching | B36: =(B35-B34)/B35 | C36: % | D36: =(B35 - B34) / B35 | E36: Tiết kiệm rõ rệt 38% - 50%
A37: TỔNG CHI PHÍ LLM API / THÁNG (2,000 tickets) | B37: =B14*B34 | C37: $/tháng | D37: =B14 * B34 | E37: Chi phí LLM toàn bộ tháng
A39: SECTION 4: CHI PHÍ THOẠI SPEECH (STT / TTS) - NẾU CÓ
A40: Sản phẩm là Text Chat Agent thuần túy (Không dùng Voice) | B40: 0 | C40: $/tháng | D40: Text-based Chat (Messenger, Zalo, Web) | E40: Không phát sinh STT/TTS
A42: SECTION 5: CHI PHÍ HẠ TẦNG, VECTOR DB & LOGGING (INFRASTRUCTURE)
A43: Vector DB (Qdrant / Pinecone Serverless) | B43: 0.003 | C43: $/ticket | D43: Pinecone pricing $0.003/query+embedding | E43: Tra cứu semantic chính sách & FAQ
A44: Logging, Tracing & Evals (LangSmith / OpenTelemetry) | B44: 0.0015 | C44: $/ticket | D44: LangSmith $0.0015/trace | E44: Lưu log & tracking audit trail
A45: Cloud Server, Egress & Webhook Execution | B45: 0.0015 | C45: $/ticket | D45: AWS Lambda / Fly.io execution | E45: Xử lý webhook & API ERP/CRM
...

Sheet 2_Pricing
A1: TAB 2: ĐỊNH GIÁ BÁN, GROSS MARGIN & SENSITIVITY STRESS TEST
A2: Xác định Giá sàn, Giá trần, Giá đề xuất và Kiểm tra ngưỡng sinh tử Breakeven Containment
A4: 1. XÁC LẬP VÙNG GIÁ BÁN: GIÁ SÀN (COST x 3) VÀ GIÁ TRẦN (ANCHORING)
A5: Khoản mục | B5: Giá trị | C5: Đơn vị | D5: Công thức / Nguồn cơ sở | E5: Ghi chú
A6: Cost/Job cơ sở (Biến thể B - Managed Outcome) | B6: ='1_Cost_Job'!B77 | C6: $/job | D6: Lấy từ Tab 1 (='1_Cost_Job'!B77) | E6: Chi phí trực tiếp đầy đủ 5 thành phần
A7: Giá SÀN tối thiểu (= 3 x Cost/Job) | B7: =B6*3 | C7: $/job | D7: =B6 * 3 | E7: Đảm bảo Gross Margin >= 66.7% cover Overhead/R&D
A8: Neo giá trần 1: Theo giá trị tiết kiệm cho khách | B8: 0.75 | C8: $/job | D8: Tiết kiệm lương ca đêm ($400/tháng cho 1,640 jobs ~ $0.24/job, lấy 25-30% tổng ROI) | E8: Khách sẵn sàng chi khi thấy ROI 3x
A9: Neo giá trần 2: Theo chi phí nhân sự con người | B9: 0.9 | C9: $/job | D9: Chi phí 1 ticket do người làm tại VN/SEA ≈ $0.60 - $0.90 | E9: Tính theo 50-70% chi phí nhân sự
A10: Benchmark đối thủ thị trường (Intercom Fin) | B10: 0.99 | C10: $/resolution | D10: Intercom Fin niêm yết $0.99/resolution | E10: Mức trần ngành toàn cầu
A11: GIÁ BÁN ĐỀ XUẤT (PROPOSED PRICE) | B11: 0.6 | C11: $/resolution | D11: Nằm giữa Giá sàn ($0.504) và Giá trần ($0.75 - $0.99) | E11: Rất cạnh tranh với Intercom ($0.99) và Zendesk ($1.50)
A12: Quy đổi Giá bán đề xuất sang VNĐ (tỷ giá 26,000) | B12: =B11*26000 | C12: VNĐ/job | D12: =B11 * 26,000 | E12: Khoảng 15,600 VNĐ / ticket hoàn thành
A13: Gross Margin $ trên 1 Job hoàn thành | B13: =B11-B6 | C13: $/job | D13: =Giá bán (B11) - Cost/Job (B6) | E13: Lợi nhuận gộp trên mỗi job hoàn thành
A14: GROSS MARGIN % TẠI MỨC 82% CONTAINMENT | B14: =(B11-B6)/B11 | C14: % | D14: =(B11 - B6) / B11 | E14: MỤC TIÊU >= 60% (Đạt chuẩn xuất sắc 72.0%)
A16: 2. BẢNG SENSITIVITY STRESS TEST: ĐỘ NHẠY THEO CONTAINMENT RATE
A17: Tỷ lệ Containment % | B17: Số Job Hoàn thành | C17: Số Ca Escalate | D17: Chi phí Tháng Biến thể B | E17: Cost / Job Hoàn thành | F17: Gross Margin % ở giá $0.60 | G17: Đánh giá An toàn Tài chính
A18: 0.5 | B18: =2000*A18 | C18: =2000*(1-A18) | D18: ='1_Cost_Job'!B70 + C18*('1_Cost_Job'!B60/60)*'1_Cost_Job'!B61 | E18: =D18/B18 | F18: =($B$11-E18)/$B$11 | G18: 🟥 NGUY HIỂM (GM < 50% - Lỗ nặng/Biên mỏng)
A19: 0.6 | B19: =2000*A19 | C19: =2000*(1-A19) | D19: ='1_Cost_Job'!B70 + C19*('1_Cost_Job'!B60/60)*'1_Cost_Job'!B61 | E19: =D19/B19 | F19: =($B$11-E19)/$B$11 | G19: 🟨 CẢNH BÁO (Dưới ngưỡng chuẩn 60% GM)
A20: 0.684 | B20: =2000*A20 | C20: =2000*(1-A20) | D20: ='1_Cost_Job'!B70 + C20*('1_Cost_Job'!B60/60)*'1_Cost_Job'!B61 | E20: =D20/B20 | F20: =($B$11-E20)/$B$11 | G20: 🟩 BREAKEVEN NGƯỠNG SỐNG CÒN (GM = 60.0%)
A21: 0.7 | B21: =2000*A21 | C21: =2000*(1-A21) | D21: ='1_Cost_Job'!B70 + C21*('1_Cost_Job'!B60/60)*'1_Cost_Job'!B61 | E21: =D21/B21 | F21: =($B$11-E21)/$B$11 | G21: 🟩 AN TOÀN CAO (Biên lợi nhuận xuất sắc)
A22: 0.8 | B22: =2000*A22 | C22: =2000*(1-A22) | D22: ='1_Cost_Job'!B70 + C22*('1_Cost_Job'!B60/60)*'1_Cost_Job'!B61 | E22: =D22/B22 | F22: =($B$11-E22)/$B$11 | G22: 🟩 AN TOÀN CAO (Biên lợi nhuận xuất sắc)
A23: 0.82 | B23: =2000*A23 | C23: =2000*(1-A23) | D23: ='1_Cost_Job'!B70 + C23*('1_Cost_Job'!B60/60)*'1_Cost_Job'!B61 | E23: =D23/B23 | F23: =($B$11-E23)/$B$11 | G23: 🟩 BASELINE HIỆN TẠI (GM = 72.0% - Rất tốt)
A24: 0.9 | B24: =2000*A24 | C24: =2000*(1-A24) | D24: ='1_Cost_Job'!B70 + C24*('1_Cost_Job'!B60/60)*'1_Cost_Job'!B61 | E24: =D24/B24 | F24: =($B$11-E24)/$B$11 | G24: 🟩 AN TOÀN CAO (Biên lợi nhuận xuất sắc)
A27: 3. NGƯỠNG SINH TỬ BREAKEVEN CONTAINMENT (KẾT NỐI EVALS -> PRICING)
A28: Giá bán đề xuất | B28: =$B$11 | C28: $/resolution | D28: Mức giá niêm yết | E28: Giá bán chốt
A29: Gross Margin mục tiêu tối thiểu | B29: 0.6 | C29: % | D29: Ngưỡng an toàn ngành SaaS/AI | E29: Target chuẩn ngành
A30: Cost/Job tối đa cho phép để đạt GM 60% | B30: =B28*(1-B29) | C30: $/job | D30: =Giá bán * (1 - GM mục tiêu) = $0.60 * 0.40 | E30: Trần chi phí đơn vị
A31: BREAKEVEN CONTAINMENT RATE YÊU CẦU | B31: 0.684 | C31: % | D31: Giải phương trình: (59.54 + 0.60*(2000-R)) / R <= $0.240 -> R >= 1,368 -> 68.4% | E31: NGƯỠNG SỐNG CÒN CỦA Evals
A32: Containment Rate thực tế từ Evals | B32: ='1_Cost_Job'!B15 | C32: % | D32: Lấy từ kết quả Eval / Giả định Tab 1 | E32: Kết quả thực tế hôm nay
A33: Biên an toàn (Safety Margin = Thực tế - Breakeven) | B33: =B32-B31 | C33: % | D33: =B32 - B31 (82.0% - 68.4%) | E33: VÙNG AN TOÀN DƯ +13.6% (Đảm bảo mô hình luôn có lãi)

Sheet 3_Value_Metric
A1: TAB 3: ĐÁNH GIÁ MA TRẬN ATTRIBUTION x AUTONOMY & CHỌN VALUE METRIC
A2: Chấm điểm khả năng quy kết giá trị (Attribution) và mức độ tự động hóa (Autonomy)
A4: 1. CHẤM ĐIỂM ATTRIBUTION (KHẢ NĂNG ĐO LƯỜNG & QUY KẾT KẾT QUẢ CHO AI)
A5: Tiêu chí đánh giá | B5: Điểm (1-5) | C5: Bằng chứng thực tế của sản phẩm | D5: Ghi chú chấm điểm
A6: Khách hàng có đồng thuận về định nghĩa 'ticket giải quyết xong' không? | B6: 5 | C6: Định nghĩa rõ: Khách xác nhận 'Cảm ơn/Đã hiểu' hoặc không gửi thêm tin nhắn sau 24h | D6: Định nghĩa chặt chẽ không tranh cãi
A7: Hệ thống có log rõ ràng tin nhắn cuối cùng là bot xử lý mà không cần chuyển người? | B7: 5 | C7: Audit log lưu lại toàn bộ message trace, trạng thái closed by AI trong cơ sở dữ liệu | D7: Attribution kỹ thuật 100%
A8: Có thể đo lường tỷ lệ CSAT hoặc tỷ lệ no-reopen tự động không? | B8: 4 | C8: Tự động gửi khảo sát 1-click CSAT sau khi đóng ticket và đo reopen rate trong 24h | D8: Đo lường định lượng chính xác
A9: Khách hàng có phân biệt được ticket do AI giải quyết vs ticket nhân sự làm? | B9: 5 | C9: Phân tách rõ ràng trên Dashboard báo cáo: Ticket Resolved by AI vs Escalate to Human | D9: Rõ ràng minh bạch trên hoá đơn
A10: Có cơ chế tự động miễn phí/hoàn tiền khi ticket bị escalate hoặc khách phàn nàn? | B10: 5 | C10: Chỉ tính tiền khi status = 'AI Resolved'; toàn bộ ca Escalate tính $0 tiền phí outcome | D10: Khách hàng hoàn toàn tin tưởng
A11: TỔNG ĐIỂM ATTRIBUTION (Max: 25) | B11: =SUM(B6:B10) | C11: ATTRIBUTION CAO (>= 20/25) -> ĐỦ ĐIỀU KIỆN BÁN OUTCOME | D11: Kết quả xuất sắc
A13: 2. CHẤM ĐIỂM AUTONOMY (MỨC ĐỘ TỰ ĐỘNG HÓA CỦA AI TRONG QUY TRÌNH)
A14: Tiêu chí đánh giá | B14: Điểm (1-5) | C14: Bằng chứng thực tế của sản phẩm | D14: Ghi chú chấm điểm
A15: AI có tự động kết nối API CRM/ERP tra cứu thông tin đơn hàng/vận đơn không? | B15: 5 | C15: Agent tự gọi tool check_order_status(), get_policy_rag() qua API | D15: Tự động hóa dữ liệu đầu vào
A16: AI có tự ra quyết định phản hồi và đóng ticket mà không cần người bấm duyệt? | B16: 5 | C16: Tự động gửi câu trả lời và cập nhật trạng thái đơn hàng trên Pancake/Zalo OA | D16: Không cần human approval từng tin
A17: Tỷ lệ Containment rate đạt mức cao trong môi trường thực tế? | B17: 4 | C17: Đạt 82.0% Containment rate trên tập test pilot | D17: Tự xử lý phần lớn ticket
A18: Hệ thống có tự động nhận diện intent phức tạp để escalate an toàn? | B18: 5 | C18: Fallback an toàn 100% khi gặp khiếu nại gay gắt hoặc ngoài tri thức | D18: Tránh hallucination gây hại
A19: Mức độ can thiệp của con người trong quá trình xử lý ticket? | B19: 4 | C19: Chỉ can thiệp ở 18% ca escalate; 82% còn lại hoàn toàn không có người chạm vào | D19: Mức độ can thiệp cực thấp
A20: TỔNG ĐIỂM AUTONOMY (Max: 25) | B20: =SUM(B15:B19) | C20: AUTONOMY CAO (>= 20/25) -> AI TỰ CHẠY ĐỘC LẬP TỐT | D20: Kết quả xuất sắc
A22: 3. KẾT QUẢ GỢI Ý VALUE METRIC TỪ MA TRẬN & BENCHMARK THỊ TRƯỜNG
A23: Gợi ý từ Ma trận Attribution x Autonomy: | B23: OUTCOME-BASED hoặc HYBRID (Base + Outcome)
A25: 4. BENCHMARK 3 SẢN PHẨM THẬT CÙNG LOẠI JOB
A26: Sản phẩm Benchmark | B26: Value Metric áp dụng | C26: Mức giá niêm yết hiện hành | D26: Nguồn tham chiếu xác thực
A27: 1. Intercom Fin | B27: Outcome (Per Resolution) | C27: $0.99 / resolution (Không tính phí seat khi cắm Helpdesk ngoài) | D27: https://fin.ai/pricing/
A28: 2. Zendesk AI | B28: Outcome (Automated Resolution Tiers) | C28: $1.50 / automated resolution | D28: https://zendesk.com/pricing
A29: 3. Salesforce Agentforce | B29: Usage / Hybrid (Flex Credits + User) | C29: $2.00 / conversation hoặc $0.10 / action | D29: https://salesforce.com/agentforce/pricing/
A31: 5. CHỐT VALUE METRIC & DECISION NOTE (3 CÂU BẢO VỆ)
A32: 1. Đơn vị tính tiền chốt: | B32: HYBRID: Phí nền $99/tháng (bao gồm 200 resolutions) + $0.50/resolution vượt định mức (hoặc $0.60/resolution thuần).
A33: 2. Bằng chứng Attribution & Autonomy: | B33: Attribution đạt 24/25 và Autonomy đạt 23/25, chứng minh qua Eval 82% Containment rate và hệ thống log trace không thể tranh cãi.
A34: 3. Lý do thị trường (Market Justification): | B34: SME Việt Nam cần phí nền thấp để yên tâm setup, đồng thời đơn giá $0.50 - $0.60/resolution giúp khách hàng thấy rẻ hơn 50% so với thuê người trực đêm mà không sợ hóa đơn bị thả nổi.

Sheet 4_Channel_Fit
A1: TAB 4: ĐÁNH GIÁ KÊNH GTM & CHANNEL AFFORDABILITY TEST
A2: Tính toán Ngân sách CAC, Deal Capacity của Sales Rep và Chấm điểm lựa chọn 1 Kênh Phân Phối Cốt Lõi
A4: 1. TÍNH TOÁN NGÂN SÁCH CAC TỐI ĐA CHO PHÉP (CHANNEL AFFORDABILITY)
A5: Khoản mục | B5: Giá trị | C5: Đơn vị | D5: Công thức / Nguồn cơ sở | E5: Ghi chú
A6: ARPU trung bình / khách hàng / tháng | B6: 300 | C6: $/tháng | D6: Ước tính gói Hybrid ~500 resolutions/tháng | E6: Doanh thu trung bình trên 1 shop SME
A7: Gross Margin % lấy từ Tab 2 | B7: ='2_Pricing'!B14 | C7: % | D7: Lấy từ Tab 2 (='2_Pricing'!B14) | E7: Biên lợi nhuận gộp
A8: Phân khúc khách hàng mục tiêu | B8: SMB | C8: Segment | D8: SMB / Mid-market / Enterprise | E8: Khách hàng E-commerce & Retail SME
A9: Thời gian hoàn vốn CAC tối đa cho phép (Payback Months) | B9: 12 | C9: tháng | D9: Chuẩn Bessemer 2024: SMB < 12 tháng | E9: Ngưỡng hoàn vốn tối đa
A10: NGÂN SÁCH CAC TỐI ĐA CHO PHÉP / KHÁCH HÀNG | B10: =B6*B7*B9 | C10: $/khách | D10: =ARPU * Gross Margin * Payback Months | E10: SỐ TIỀN TỐI ĐA ĐƯỢC PHÉP CHI ĐỂ CÓ 1 KHÁCH
A11: Quy đổi Ngân sách CAC sang VNĐ (tỷ giá 26,000) | B11: =B10*26000 | C11: VNĐ/khách | D11: =B10 * 26,000 | E11: Tương đương ~67.3 triệu VNĐ / khách
A13: 2. KIỂM TRA TÍNH KHẢ THI CỦA SALES-LED MOTION (INSIDE SALES CAPACITY)
A14: Quota doanh số 1 Account Executive (AE) / năm | B14: 120000 | C14: $/năm | D14: Giả định quota AE thị trường SEA/VN | E14: Chỉ tiêu doanh thu 1 sales
A15: Giá trị hợp đồng hàng năm (ACV = ARPU x 12) | B15: =B6*12 | C15: $/năm | D15: =B6 * 12 | E15: ACV = $3,600 / năm
A16: Số deal 1 AE phải chốt / năm | B16: =B14/B15 | C16: deals/năm | D16: =Quota / ACV = $120k / $3.6k | E16: Số lượng deal cần hoàn thành
A17: Số ngày làm việc trong năm | B17: 250 | C17: ngày | D17: 50 tuần x 5 ngày | E17: Thời gian làm việc thực tế
A18: Số deal 1 AE phải chốt / ngày làm việc | B18: =B16/B17 | C18: deals/ngày | D18: =Deals / 250 ngày = 33.3 / 250 | E18: 0.13 deal/ngày (~1 deal mỗi 7.5 ngày) -> Về số deal thì khả thi
A19: Cost per Opportunity thực tế của Sales Rep (ICONIQ 2026) | B19: 6300 | C19: $/opp | D19: Benchmark ICONIQ 2026 cho phân khúc SMB | E19: Chi phí để tạo ra 1 cơ hội demo sales
A20: Tỷ lệ chốt thành công của Sales (Win Rate) | B20: 0.25 | C20: % | D20: Benchmark chuẩn ngành B2B SaaS 25% | E20: 1/4 cơ hội thành khách trả tiền
A21: CAC THỰC TẾ ƯỚC TÍNH NẾU DÙNG ĐỘI SALES REP | B21: =B19/B20 | C21: $/khách | D21: =Cost per Opp / Win Rate = $6,300 / 0.25 | E21: Chi phí để có 1 khách qua sales
A22: HỆ SỐ LỆCH (CAC THỰC TẾ SALES / NGÂN SÁCH CAC) | B22: =B21/B10 | C22: lần | D22: =$25,200 / $2,592 | E22: 🟥 LỆCH 9.7 LẦN -> SALES-LED THUẦN LÀ BẤT KHẢ THI
A24: 3. SCORECARD CHẤM ĐIỂM 3 KÊNH PHÂN PHỐI (PLG vs PARTNER-LED vs SALES-LED)
A25: Tiêu chí đánh giá (Thang điểm 1-5) | B25: PLG (Product-Led) | C25: Partner-Led (Platform) | D25: Sales-Led (Direct Sales) | E25: Trọng số & Ý nghĩa
A26: 1. Chi phí tiếp cận khách hàng (CAC Affordability) | B26: 4 | C26: 5 | D26: 1 | E26: Partner-Led CAC thấp nhất nhờ đòn bẩy
A27: 2. Mức độ phù hợp với Pain Moment (Zero Friction) | B27: 3 | C27: 5 | D27: 2 | E27: Partner-Led nhúng thẳng vào Pancake/Zalo
A28: 3. Tốc độ triển khai & ra mắt trong 90 ngày | B28: 4 | C28: 5 | D28: 2 | E28: Cắm webhook partner có sẵn khách ngay
A29: 4. Tỷ lệ chuyển đổi & niềm tin ban đầu của khách | B29: 3 | C29: 5 | D29: 3 | E29: Partner uy tín bảo chứng
A30: 5. Kh khả năng mở rộng (Scalability) không phình người | B30: 5 | C30: 4 | D30: 2 | E30: PLG và Partner scale rất nhanh
A31: 6. Mức độ kiểm soát quan hệ khách hàng | B31: 3 | C31: 3 | D31: 5 | E31: Sales-Led giữ quan hệ tốt nhất
A32: TỔNG ĐIỂM ĐÁNH GIÁ (Max: 30) | B32: =SUM(B26:B31) | C32: =SUM(C26:C31) | D32: =SUM(D26:D31) | E32: PARTNER-LED ĐẠT ĐIỂM CAO NHẤT (27/30)
A34: 4. KẾT LUẬN KÊNH GTM CHỐT CHO 90 NGÀY ĐẦU TIÊN
A35: Kênh GTM lựa chọn: | B35: PARTNER-LED (Cắm vào nền tảng E-commerce/Helpdesk có sẵn) kết hợp PLG Freemium 50 resolutions.
A36: Tên Partner cụ thể: | B36: Pancake / BotCake (Quản lý chat đa kênh cho 50,000+ shop tại VN), Haravan & Sapo App Store, Zalo OA.
A37: Giá trị mang lại cho Partner: | B37: Giúp Partner tăng retention khách hàng, giảm áp lực hạ tầng CSKH cho merchant, chia sẻ 20% doanh thu revenue share.
A38: Trạng thái trao đổi với Partner: | B38: Đã có API Webhook kết nối 2 chiều; đã triển khai thử nghiệm Alpha Pilot với 3 merchants đang dùng Pancake.

Sheet 5_90Day_Plan
A1: TAB 5: PAIN MOMENT, KẾ HOẠCH GTM 90 NGÀY & CHECKLIST EVIDENCE PACK
A2: Chi tiết hóa Điểm chạm khách hàng, Lộ trình triển khai 3 giai đoạn và Bộ tài sản bán hàng pháp lý/bảo mật
A4: 1. PAIN MOMENT & ĐIỂM NHÚNG KHÔNG MA SÁT (ZERO-FRICTION INTEGRATION)
A5: Pain Moment - MẤY GIỜ? | B5: 22h00 đêm đến 02h00 sáng (Khung giờ vàng mua sắm online ca đêm nhưng nhân sự CSKH đã off ca).
A6: Pain Moment - ĐANG LÀM GÌ? | B6: Khách hàng nhắn tin hỏi tư vấn đổi size, check tình trạng đơn hàng, hoặc phàn nàn giao trễ. Không ai rep -> Khách huỷ đơn, đánh giá 1 sao.
A7: Pain Moment - DÙNG APP NÀO? | B7: Chủ shop / CS Lead đang mở điện thoại kiểm tra Pancake Inbox, Zalo OA hoặc Shopee/TikTok chat thấy hàng chục tin chưa trả lời.
A8: Điểm nhúng sản phẩm (Surface): | B8: Cắm thẳng qua Webhook vào Pancake / Haravan / Zalo OA. Khách hàng bấm 1-click tích hợp, KHÔNG bắt mở thêm website riêng biệt.
A10: 2. KẾ HOẠCH GTM 90 NGÀY (3 GIAI ĐOẠN: HIỂU SÂU -> ĐÒN BẨY -> MỞ RỘNG)
A11: Giai đoạn | B11: Mục tiêu trọng tâm | C11: Hành động cụ thể | D11: KPI định lượng | E11: Người chịu trách nhiệm
A12: Tháng 1 (Day 1 - 30) HIỂU SÂU & THỰC CHỨNG | B12: Làm việc tận tay với 5 Design Partners đầu tiên trên Pancake để tinh chỉnh bot. | C12: 1. Cài đặt trực tiếp cho 5 shop E-commerce (Thời trang & Mỹ phẩm). 2. Đo lường Containment rate thực tế và audit 100% lỗi escalation. 3. Hoàn thiện bộ Prompt Caching & RAG catalog. | D12: • 5 khách hàng active • Containment >= 80% • CSAT >= 4.5/5 • 0 lỗi rò rỉ dữ liệu | E12: Founder & Lead AI Engineer
A13: Tháng 2 - 3 (Day 31 - 90) ĐÒN BẨY PARTNER & PLG | B13: Ra mắt chính thức trên Pancake App Marketplace & Co-marketing. | C13: 1. Public App trên Pancake Marketplace với ưu đãi 100 resolutions free. 2. Tổ chức Webinar chia sẻ Case Study tiết kiệm 70% chi phí trực đêm. 3. Triển khai tính năng tự động nạp credits (Self-serve billing). | D13: • 50 khách hàng trả phí • MRR đạt $5,000 • CAC < $150 / khách • Containment giữ vững > 80% | E13: Growth Lead & Partner Manager
A14: Tháng 4+ (Day 91+) MỞ RỘNG & UPSELL | B14: Mở rộng sang Haravan, Sapo, Zalo OA và ra mắt tính năng Action Agent. | C14: 1. Tích hợp thêm Haravan, Sapo, Zalo OA. 2. Ra mắt Agent tự xử lý đổi trả (Refund/Exchange Action) tăng ARPU. 3. Đàm phán gói phân phối Enterprise với các chuỗi bán lẻ lớn. | D14: • 150 khách hàng trả phí • MRR đạt $15,000 • Net Retention Rate > 115% • Gross Margin > 70% | E14: CEO & Sales Lead
A16: 3. EVIDENCE PACK - 3 TÀI SẢN BÁN HÀNG ĐỂ VƯỢT QUA IT & PROCUREMENT
A17: Tài sản bán hàng | B17: Trạng thái hiện tại | C17: Nội dung chi tiết tài sản | D17: Thời hạn hoàn thành | E17: Người chịu trách nhiệm
A18: 1. Eval Results (Báo cáo đo lường chất lượng) | B18: ĐÃ CÓ (Verified) | C18: Bộ dữ liệu 500 test cases thực chiến: Factual Accuracy 96.4%, Containment Rate 82.0%, Tỷ lệ nhận diện escalation an toàn 98.8%, Không ghi nhận hallucination nghiêm trọng. | D18: Đã hoàn thành | E18: AI Lead Engineer
A19: 2. Procurement & Security Q&A (Bản cam kết bảo mật) | B19: ĐÃ CÓ (Ready) | C19: Tài liệu văn bản trả lời 3 câu hỏi sống còn của IT: 1. Zero Data Retention: Dữ liệu khách hàng không bao giờ bị dùng để train model. 2. Bảo mật AES-256 trên đường truyền và lưu trữ tại AWS Singapore. 3. Data Escrow & Export: Dễ dàng xuất toàn bộ dữ liệu khi dừng dịch vụ. | D19: Đã hoàn thành | E19: CTO & Compliance Lead
A20: 3. Pilot Report (Báo cáo thử nghiệm thực tế) | B20: ĐANG THỰC HIỆN | C20: Báo cáo thử nghiệm 3 tuần với thương hiệu thời trang D2C (quy mô 2,000 ticket/tháng): Giải quyết 1,640 ticket ca đêm, giảm thời gian phản hồi từ 35 phút xuống 6 giây, tiết kiệm 10.5 triệu VNĐ chi phí trực ca. | D20: Deadline: Day 30 | E20: Product Manager & Founder

Sheet 6_Benchmarks
A1: TAB 6: BẢNG GIÁ THAM CHIẾU NHÀ CUNG CẤP & BENCHMARK NGÀNH
A2: Dữ liệu đối soát niêm yết chính thức chốt ngày 26/08/2026 (Kèm liên kết nguồn)
A4: 1. BẢNG GIÁ API MÔ HÌNH LLM & SPEECH (CHỐT 26/08/2026)
A5: Nhà cung cấp / Mô hình | B5: Loại dịch vụ | C5: Giá Input / Cache Read | D5: Giá Output / Cache Write | E5: Đơn vị tính | F5: Đường dẫn nguồn tài liệu
A6: Anthropic Claude 3.5 Haiku | B6: LLM API | C6: $1.00 (Fresh) / $0.10 (Cache Read) | D6: $5.00 (Output) / $1.25 (Cache Write) | E6: Per 1M tokens | F6: https://platform.claude.com/docs/en/about-claude/pricing
A7: Anthropic Claude 3.5 Sonnet | B7: LLM API | C7: $3.00 (Fresh) / $0.30 (Cache Read) | D7: $15.00 (Output) / $3.75 (Cache Write) | E7: Per 1M tokens | F7: https://platform.claude.com/docs/en/about-claude/pricing
A8: Anthropic Claude 3 Opus | B8: LLM API | C8: $15.00 (Fresh) / $1.50 (Cache Read) | D8: $75.00 (Output) / $18.75 (Cache Write) | E8: Per 1M tokens | F8: https://platform.claude.com/docs/en/about-claude/pricing
A9: OpenAI GPT-5.6 Sol (Promo ⏳) | B9: LLM API | C9: $4.00 (Fresh) / $0.40 (Cache Read) | D9: $20.00 (Output) | E9: Per 1M tokens | F9: https://developers.openai.com/api/docs/pricing
A10: Google Gemini 3.7 Flash (Promo ⏳) | B10: LLM API | C10: $0.75 (Fresh) / $0.075 (Cache Read) | D10: $3.75 (Output) | E10: Per 1M tokens | F10: https://ai.google.dev/gemini-api/docs/pricing
A11: Deepgram Nova-3 (Streaming ⏳) | B11: Speech-to-Text | C11: $0.0048 (Promo) / $0.0077 (List) | D11: N/A | E11: Per phút audio | F11: https://deepgram.com/pricing
A12: AssemblyAI Universal-2 | B12: Speech-to-Text | C12: $0.0025 (Async) | D12: N/A | E12: Per phút audio | F12: https://www.assemblyai.com/pricing
A13: ElevenLabs Flash / Turbo | B13: Text-to-Speech | C13: N/A | D13: $50.00 / 1M ký tự | E13: Per 1M ký tự | F13: https://elevenlabs.io/pricing/api
A14: Google Cloud Text-to-Speech Standard | B14: Text-to-Speech | C14: N/A | D14: $4.00 / 1M ký tự | E14: Per 1M ký tự | F14: https://cloud.google.com/text-to-speech/pricing
A16: 2. BẢNG GIÁ SẢN PHẨM AI & VALUE METRIC THỰC TẾ
A18: Intercom Fin | B18: Customer Service Agent | C18: Outcome-based | D18: $0.99 / resolution | E18: Không tính phí seat khi cắm Helpdesk ngoài | F18: https://fin.ai/pricing/
A19: GitHub Copilot | B19: Developer AI Agent | C19: Hybrid (Seat + Credits) | D19: $19 / seat / tháng (kèm 1,900 credits) + $0.01/credit vượt | E19: Đổi Value Metric từ 01/06/2026 | F19: https://docs.github.com/en/copilot/get-started/plans
A20: Salesforce Agentforce | B20: Autonomous Enterprise Agent | C20: Usage (Action/Conversation) | D20: $2.00 / conversation hoặc Flex Credits $500/100,000 ($0.10/action) | E20: $5 / user / tháng phí nền | F20: https://www.salesforce.com/agentforce/pricing/
A21: Zendesk AI | B21: Support Automation | C21: Outcome-based | D21: $1.50 / automated resolution (3 bậc resolution) | E21: Gắn định nghĩa timeout theo kênh | F21: https://zendesk.com/pricing
A22: Clay | B22: GTM & Data Enrichment | C22: Hybrid | D22: $167 - $446 / tháng (không giới hạn seat) + Credits | E22: Top-up usage +30% | F22: https://www.clay.com/pricing
A23: Cursor | B23: AI Code Editor | C23: Hybrid | D23: $20 - $200 / tháng cá nhân; $40 - $120 / seat teams + usage | E23: On-demand usage tính sau | F23: https://cursor.com/pricing
A26: 3. BENCHMARK TÀI CHÍNH & GTM CHO AI-NATIVE VÀ SAAS (BESSERMER & ICONIQ)
A28: ICONIQ 2026 State of AI Report | B28: Gross Margin AI-native | C28: 52% - 53% (2026E) | D28: 59% (2027E) | E28: 84% công ty AI đẩy 1 phần chi phí token sang khách hàng | F28: https://www.iconiq.com/growth/reports/state-of-ai-2026
A29: Bessemer Venture Partners 2024 | B29: Vertical AI Gross Margin | C29: 65.0% | D29: Model cost ≈ 10% doanh thu (~25% COGS) | E29: Biên lợi nhuận gộp SaaS truyền thống: 60% - 80% | F29: https://www.bvp.com/atlas/state-of-the-cloud-2024
A30: David Skok (SaaS Metrics 2.0) | B30: LTV : CAC Ratio & Payback | C30: LTV : CAC >= 3.0x (Tốt: 7x - 8x) | D30: Payback SMB < 12 tháng, Mid < 18, Ent < 24 | E30: Tỷ lệ tăng trưởng và hiệu quả vốn tối ưu | F30: https://www.forentrepreneurs.com/saas-metrics-2/
A31: Tomasz Tunguz (Inside Sales Floor) | B31: Inside Sales Minimum ACV | C31: Tối thiểu ~$3,000 ACV | D31: Quota $500k, Loaded $100k, Attainment 75% | E31: Dưới $3,000 ACV bắt buộc dùng PLG hoặc Partner-Led | F31: https://tomtunguz.com/smallest-acv-to-justify-inside-sales-team/
A32: ICONIQ 2026 GTM Cost | B32: Cost per Opportunity | C32: SMB: $6,300 | Mid: $8,000 | Ent: $11,200 | D32: Win rate 25% -> CAC Sales = $25,200 - $44,800 | E32: Chi phí nuôi sales rep rất cao | F32: https://www.iconiq.com
